[12/Jun/2016 09:54:47 -0700] webhdfs      ERROR    Failed to determine superuser of WebHdfs at http://localhost:50070/webhdfs/v1: ('Connection aborted.', error(61, 'Connection refused'))
Traceback (most recent call last):
  File "/Users/pankajkumar/Desktop/MyRepositories/hue/desktop/libs/hadoop/src/hadoop/fs/webhdfs.py", line 149, in superuser
    sb = self.stats('/')
  File "/Users/pankajkumar/Desktop/MyRepositories/hue/desktop/libs/hadoop/src/hadoop/fs/webhdfs.py", line 236, in stats
    res = self._stats(path)
  File "/Users/pankajkumar/Desktop/MyRepositories/hue/desktop/libs/hadoop/src/hadoop/fs/webhdfs.py", line 230, in _stats
    raise ex
WebHdfsException: ('Connection aborted.', error(61, 'Connection refused'))
[12/Jun/2016 09:54:47 -0700] conf         ERROR    Failed to contact an active Resource Manager: ('Connection aborted.', error(61, 'Connection refused'))
Traceback (most recent call last):
  File "/Users/pankajkumar/Desktop/MyRepositories/hue/desktop/libs/hadoop/src/hadoop/conf.py", line 216, in test_yarn_configurations
    get_api(user, None).get_jobs(user, username=user.username, state='all', text='')
  File "/Users/pankajkumar/Desktop/MyRepositories/hue/desktop/libs/hadoop/src/hadoop/cluster.py", line 76, in decorate
    raise ex
RestException: ('Connection aborted.', error(61, 'Connection refused'))
[12/Jun/2016 09:54:47 -0700] conf         ERROR    failed to get oozie status
Traceback (most recent call last):
  File "/Users/pankajkumar/Desktop/MyRepositories/hue/desktop/libs/liboozie/src/liboozie/conf.py", line 61, in get_oozie_status
    status = str(get_oozie(user).get_oozie_status())
  File "/Users/pankajkumar/Desktop/MyRepositories/hue/desktop/libs/liboozie/src/liboozie/oozie_api.py", line 325, in get_oozie_status
    resp = self._root.get('admin/status', params)
  File "/Users/pankajkumar/Desktop/MyRepositories/hue/desktop/core/src/desktop/lib/rest/resource.py", line 98, in get
    return self.invoke("GET", relpath, params, headers=headers, allow_redirects=True)
  File "/Users/pankajkumar/Desktop/MyRepositories/hue/desktop/core/src/desktop/lib/rest/resource.py", line 79, in invoke
    urlencode=self._urlencode)
  File "/Users/pankajkumar/Desktop/MyRepositories/hue/desktop/core/src/desktop/lib/rest/http_client.py", line 163, in execute
    raise self._exc_class(ex)
RestException: ('Connection aborted.', error(61, 'Connection refused'))
[12/Jun/2016 09:54:47 -0700] views        ERROR    Error in config validation by liboozie: ('Connection aborted.', error(61, 'Connection refused'))
Traceback (most recent call last):
  File "/Users/pankajkumar/Desktop/MyRepositories/hue/desktop/core/src/desktop/views.py", line 472, in _get_config_errors
    for confvar, error in validator(request.user):
  File "/Users/pankajkumar/Desktop/MyRepositories/hue/desktop/libs/liboozie/src/liboozie/conf.py", line 86, in config_validator
    intrumentation = api.get_instrumentation()
  File "/Users/pankajkumar/Desktop/MyRepositories/hue/desktop/libs/liboozie/src/liboozie/oozie_api.py", line 304, in get_instrumentation
    resp = self._root.get('admin/instrumentation', params)
  File "/Users/pankajkumar/Desktop/MyRepositories/hue/desktop/core/src/desktop/lib/rest/resource.py", line 98, in get
    return self.invoke("GET", relpath, params, headers=headers, allow_redirects=True)
  File "/Users/pankajkumar/Desktop/MyRepositories/hue/desktop/core/src/desktop/lib/rest/resource.py", line 79, in invoke
    urlencode=self._urlencode)
  File "/Users/pankajkumar/Desktop/MyRepositories/hue/desktop/core/src/desktop/lib/rest/http_client.py", line 163, in execute
    raise self._exc_class(ex)
RestException: ('Connection aborted.', error(61, 'Connection refused'))
[12/Jun/2016 09:54:48 -0700] conf         ERROR    The application won't work without a running HiveServer2.
Traceback (most recent call last):
  File "/Users/pankajkumar/Desktop/MyRepositories/hue/apps/beeswax/src/beeswax/conf.py", line 216, in config_validator
    raise e
StructuredThriftTransportException: Could not connect to localhost:10000 (code THRIFTTRANSPORT): TTransportException('Could not connect to localhost:10000',)
[12/Jun/2016 09:54:48 -0700] conf         ERROR    Failed to access Hive warehouse: /user/hive/warehouse
Traceback (most recent call last):
  File "/Users/pankajkumar/Desktop/MyRepositories/hue/apps/beeswax/src/beeswax/conf.py", line 226, in config_validator
    fs.stats(warehouse)
  File "/Users/pankajkumar/Desktop/MyRepositories/hue/desktop/core/src/desktop/lib/fs/proxyfs.py", line 102, in stats
    return self._get_fs(path).stats(path)
  File "/Users/pankajkumar/Desktop/MyRepositories/hue/desktop/libs/hadoop/src/hadoop/fs/webhdfs.py", line 236, in stats
    res = self._stats(path)
  File "/Users/pankajkumar/Desktop/MyRepositories/hue/desktop/libs/hadoop/src/hadoop/fs/webhdfs.py", line 230, in _stats
    raise ex
WebHdfsException: ('Connection aborted.', error(61, 'Connection refused'))
[12/Jun/2016 09:54:48 -0700] api          ERROR    failed to load the HBase clusters
Traceback (most recent call last):
  File "/Users/pankajkumar/Desktop/MyRepositories/hue/apps/hbase/src/hbase/api.py", line 64, in getClusters
    full_config = json.loads(conf.HBASE_CLUSTERS.get().replace("'", "\""))
  File "/System/Library/Frameworks/Python.framework/Versions/2.7/lib/python2.7/json/__init__.py", line 338, in loads
    return _default_decoder.decode(s)
  File "/System/Library/Frameworks/Python.framework/Versions/2.7/lib/python2.7/json/decoder.py", line 366, in decode
    obj, end = self.raw_decode(s, idx=_w(s, 0).end())
  File "/System/Library/Frameworks/Python.framework/Versions/2.7/lib/python2.7/json/decoder.py", line 384, in raw_decode
    raise ValueError("No JSON object could be decoded")
ValueError: No JSON object could be decoded
[12/Jun/2016 09:54:48 -0700] api          ERROR    failed to load the HBase clusters
Traceback (most recent call last):
  File "/Users/pankajkumar/Desktop/MyRepositories/hue/apps/hbase/src/hbase/api.py", line 64, in getClusters
    full_config = json.loads(conf.HBASE_CLUSTERS.get().replace("'", "\""))
  File "/System/Library/Frameworks/Python.framework/Versions/2.7/lib/python2.7/json/__init__.py", line 338, in loads
    return _default_decoder.decode(s)
  File "/System/Library/Frameworks/Python.framework/Versions/2.7/lib/python2.7/json/decoder.py", line 366, in decode
    obj, end = self.raw_decode(s, idx=_w(s, 0).end())
  File "/System/Library/Frameworks/Python.framework/Versions/2.7/lib/python2.7/json/decoder.py", line 384, in raw_decode
    raise ValueError("No JSON object could be decoded")
ValueError: No JSON object could be decoded
[12/Jun/2016 09:54:48 -0700] api          ERROR    failed to load the HBase clusters
Traceback (most recent call last):
  File "/Users/pankajkumar/Desktop/MyRepositories/hue/apps/hbase/src/hbase/api.py", line 64, in getClusters
    full_config = json.loads(conf.HBASE_CLUSTERS.get().replace("'", "\""))
  File "/System/Library/Frameworks/Python.framework/Versions/2.7/lib/python2.7/json/__init__.py", line 338, in loads
    return _default_decoder.decode(s)
  File "/System/Library/Frameworks/Python.framework/Versions/2.7/lib/python2.7/json/decoder.py", line 366, in decode
    obj, end = self.raw_decode(s, idx=_w(s, 0).end())
  File "/System/Library/Frameworks/Python.framework/Versions/2.7/lib/python2.7/json/decoder.py", line 384, in raw_decode
    raise ValueError("No JSON object could be decoded")
ValueError: No JSON object could be decoded
[12/Jun/2016 09:54:48 -0700] conf         ERROR    The application won't work without a running HBase Thrift Server v1.
Traceback (most recent call last):
  File "/Users/pankajkumar/Desktop/MyRepositories/hue/apps/hbase/src/hbase/conf.py", line 81, in config_validator
    api.getTableList(cluster_name)
  File "/Users/pankajkumar/Desktop/MyRepositories/hue/apps/hbase/src/hbase/api.py", line 140, in getTableList
    return [{'name': name, 'enabled': client.isTableEnabled(name, doas=self.user.username)} for name in client.getTableNames(doas=self.user.username)]
  File "/Users/pankajkumar/Desktop/MyRepositories/hue/desktop/core/src/desktop/lib/thrift_util.py", line 378, in wrapper
    raise StructuredThriftTransportException(e, error_code=502)
StructuredThriftTransportException: Could not connect to localhost:9090 (code THRIFTTRANSPORT): TTransportException('Could not connect to localhost:9090',)
[12/Jun/2016 09:54:48 -0700] conf         ERROR    No available Impalad to send queries to.
Traceback (most recent call last):
  File "/Users/pankajkumar/Desktop/MyRepositories/hue/apps/impala/src/impala/conf.py", line 186, in config_validator
    raise ex
StructuredThriftTransportException: Could not connect to localhost:21050 (code THRIFTTRANSPORT): TTransportException('Could not connect to localhost:21050',)
[12/Jun/2016 09:54:48 -0700] conf         ERROR    failed to get oozie status
Traceback (most recent call last):
  File "/Users/pankajkumar/Desktop/MyRepositories/hue/desktop/libs/liboozie/src/liboozie/conf.py", line 61, in get_oozie_status
    status = str(get_oozie(user).get_oozie_status())
  File "/Users/pankajkumar/Desktop/MyRepositories/hue/desktop/libs/liboozie/src/liboozie/oozie_api.py", line 325, in get_oozie_status
    resp = self._root.get('admin/status', params)
  File "/Users/pankajkumar/Desktop/MyRepositories/hue/desktop/core/src/desktop/lib/rest/resource.py", line 98, in get
    return self.invoke("GET", relpath, params, headers=headers, allow_redirects=True)
  File "/Users/pankajkumar/Desktop/MyRepositories/hue/desktop/core/src/desktop/lib/rest/resource.py", line 79, in invoke
    urlencode=self._urlencode)
  File "/Users/pankajkumar/Desktop/MyRepositories/hue/desktop/core/src/desktop/lib/rest/http_client.py", line 163, in execute
    raise self._exc_class(ex)
RestException: ('Connection aborted.', error(61, 'Connection refused'))
[12/Jun/2016 09:54:48 -0700] conf         ERROR    failed to get oozie status
Traceback (most recent call last):
  File "/Users/pankajkumar/Desktop/MyRepositories/hue/desktop/libs/liboozie/src/liboozie/conf.py", line 61, in get_oozie_status
    status = str(get_oozie(user).get_oozie_status())
  File "/Users/pankajkumar/Desktop/MyRepositories/hue/desktop/libs/liboozie/src/liboozie/oozie_api.py", line 325, in get_oozie_status
    resp = self._root.get('admin/status', params)
  File "/Users/pankajkumar/Desktop/MyRepositories/hue/desktop/core/src/desktop/lib/rest/resource.py", line 98, in get
    return self.invoke("GET", relpath, params, headers=headers, allow_redirects=True)
  File "/Users/pankajkumar/Desktop/MyRepositories/hue/desktop/core/src/desktop/lib/rest/resource.py", line 79, in invoke
    urlencode=self._urlencode)
  File "/Users/pankajkumar/Desktop/MyRepositories/hue/desktop/core/src/desktop/lib/rest/http_client.py", line 163, in execute
    raise self._exc_class(ex)
RestException: ('Connection aborted.', error(61, 'Connection refused'))
[12/Jun/2016 09:54:48 -0700] conf         ERROR    failed to get spark status
Traceback (most recent call last):
  File "/Users/pankajkumar/Desktop/MyRepositories/hue/apps/spark/src/spark/conf.py", line 92, in get_spark_status
    get_api(user).get_status()
  File "/Users/pankajkumar/Desktop/MyRepositories/hue/apps/spark/src/spark/job_server_api.py", line 84, in get_status
    return self._root.get('sessions')
  File "/Users/pankajkumar/Desktop/MyRepositories/hue/desktop/core/src/desktop/lib/rest/resource.py", line 98, in get
    return self.invoke("GET", relpath, params, headers=headers, allow_redirects=True)
  File "/Users/pankajkumar/Desktop/MyRepositories/hue/desktop/core/src/desktop/lib/rest/resource.py", line 79, in invoke
    urlencode=self._urlencode)
  File "/Users/pankajkumar/Desktop/MyRepositories/hue/desktop/core/src/desktop/lib/rest/http_client.py", line 163, in execute
    raise self._exc_class(ex)
RestException: ('Connection aborted.', error(61, 'Connection refused'))
